Workbook

Sheet README
A1: WellGTM — Market Research Workbook
A2: Generated by analysis/build_pm_artifacts.py. Yellow cells = editable inputs; green = formulas.
A4: Sheet | B4: Contents | C4: Related document
A5: Country_Data | B5: Indicators for 30 candidate markets (UN Comtrade, World Bank) + preliminary screening scores | C5: docs/pm/03_data_analysis.md
A6: Korea_Exports_HS | B6: Korea's exports by category 2015-2025 (US$ M, Korea-reported) | C6: docs/pm/03_data_analysis.md
A7: TAM_SAM_SOM | B7: Market sizing with editable SAM membership and SOM share-gain scenarios (formulas) | C7: docs/pm/02_market_analysis.md §8
A8: Competitors | B8: Competitor & alternative analysis | C8: docs/pm/09_market_research_report.md §3
A9: Market_Trends | B9: B2B and K-food market trends with sources | C9: docs/pm/09_market_research_report.md §2
A10: ROI_Model | B10: Illustrative ROI model; all inputs are placeholder assumptions | C10: docs/pm/08_value_proposition_canvas.md §4
A11: VPC_Fit | B11: Value proposition canvas fit map (pain → reliever → feature → proof) | C11: docs/pm/08_value_proposition_canvas.md
A12: Personas | B12: Persona summary | C12: docs/pm/10_user_personas.md
A13: Interview_Plan | B13: Recruitment targets per persona and status tracker | C13: docs/pm/09_market_research_report.md §6
A14: Interview_Log | B14: One row per interview; paste notes, tag pains/gains | C14: docs/pm/09_market_research_report.md §6
A15: Survey_Responses | B15: Paste the Microsoft Forms export (Open in Excel) here; headers match the survey | C15: workbooks/WellGTM_client_survey_for_MS_Forms.docx
... A18: Roadmap | B18: Release plan with monthly Gantt grid (conditional formatting) | C18: docs/pm/11_product_roadmap.md

Sheet Country_Data
A1: Candidate market indicators
A2: Sources: UN Comtrade public API, World Bank WDI (retrieved 2026-10-29). Hubs flagged; RUS sanctioned; TWN not a Comtrade reporter.
A4: ISO3 | B4: Latest import year | C4: Category imports (US$ M) | D4: Import value CAGR 5y | E4: Import volume CAGR 5y | F4: Unit price CAGR 5y | G4: Imports from Korea (US$ M, partner-reported) | H4: Korea share of imports | I4: Korea exports 2025 (US$ M, Korea-reported) | J4: Korea export CAGR 2020-25 | K4: GDP per capita (US$) | L4: Population (M) | M4: GDP growth avg 2021-25 (%) | N4: LPI score | O4: Re-export hub | P4: Preliminary score (0-100) | Q4: P(TOP3) random weights
A5: USA | B5: 2025 | C5: 20938.479 | D5: 0.12783074 | E5: 0.054810372 | F5: 0.069226062 | G5: 204.53423 | H5: 0.0097683426 | I5: 198.83817 | J5: 0.12503177 | K5: 90026.516 | L5: 341.78486 | M5: 3.3130337 | N5: 3.8 | P5: 77.303074 | Q5: 0.8668
A6: JPN | B6: 2025 | C6: 1600.2683 | D6: 0.071955744 | E6: 0.0031418866 | F6: 0.068598329 | G6: 107.11738 | H6: 0.066937136 | I6: 147.88018 | J6: 0.036322362 | K6: 35951.045 | L6: 123.36673 | M6: 1.3139314 | N6: 3.9 | P6: 56.878258 | Q6: 0.094
A7: CHN | B7: 2025 | C7: 2071.5552 | D7: 0.045705834 | E7: -0.0078997274 | F7: 0.054032403 | G7: 93.930646 | H7: 0.045343058 | I7: 101.43125 | J7: 0.053288969 | K7: 13861.97 | L7: 1406.585 | M7: 5.4076989 | N7: 3.7 | P7: 73.420882 | Q7: 0.7532
A8: CAN | B8: 2025 | C8: 4964.2107 | D8: 0.098319148 | E8: 0.014927052 | F8: 0.082165606 | G8: 42.41361 | H8: 0.0085438777 | I8: 36.62268 | J8: 0.14089287 | K8: 55697.664 | L8: 41.651653 | M8: 3.277597 | N8: 4 | P8: 61.858162 | Q8: 0.3868
A9: PHL | B9: 2025 | C9: 844.66075 | D9: 0.14769159 | E9: 0.10257377 | F9: 0.040920458 | G9: 10.312898 | H9: 0.012209515 | I9: 33.368027 | J9: 0.19709896 | K9: 4170.7235 | L9: 116.78696 | M9: 5.7863624 | N9: 3.3 | P9: 65.354175 | Q9: 0.2066
A10: TWN | I10: 30.990338 | J10: -0.0077879566
A11: AUS | B11: 2025 | C11: 2217.4183 | D11: 0.081634055 | G11: 27.433249 | H11: 0.012371707 | I11: 30.029187 | J11: 0.055663476 | K11: 65129.723 | L11: 27.614411 | M11: 2.5135241 | N11: 3.7 | P11: 52.448569 | Q11: 0
A12: VNM | B12: 2023 | C12: 453.48006 | D12: 0.078490496 | E12: 0.024099413 | F12: 0.053111136 | G12: 23.93495 | H12: 0.052780601 | I12: 29.472422 | J12: 0.017908915 | K12: 5065.9909 | L12: 101.59853 | M12: 6.2256541 | N12: 3.3 | P12: 58.158075 | Q12: 0
A13: HKG | B13: 2025 | C13: 1113.9642 | D13: 0.04371896 | E13: 0.029597032 | F13: 0.013715975 | G13: 25.997083 | H13: 0.02333745 | I13: 27.473755 | J13: -0.015441358 | K13: 56983.066 | L13: 7.4989 | M13: 2.4073018 | N13: 4 | O13: Yes
A14: RUS | B14: 2021 | C14: 1349.0763 | D14: 0.12038317 | E14: 0.09844045 | F14: 0.019976247 | G14: 11.785077 | H14: 0.0087356637 | I14: 16.811672 | J14: 0.12686898 | K14: 17546.609 | L14: 143.51333 | M14: 2.8841183 | N14: 2.6
A15: MNG | B15: 2023 | C15: 192.76041 | D15: 0.11075921 | E15: 0.034710732 | F15: 0.073497331 | G15: 7.6731275 | H15: 0.039806553 | I15: 16.403248 | J15: 0.37000613 | K15: 7108.2274 | L15: 3.568978 | M15: 5.2115103 | N15: 2.5 | P15: 52.085074 | Q15: 0.0154
A16: MYS | B16: 2025 | C16: 760.30598 | D16: 0.13134152 | E16: 0.11735814 | F16: 0.012514687 | G16: 9.3575272 | H16: 0.012307581 | I16: 11.801157 | J16: 0.033365039 | K16: 13124.555 | L16: 35.977838 | M16: 5.2321761 | N16: 3.6 | P16: 62.046758 | Q16: 0.0994
A17: NLD | B17: 2025 | C17: 6392.7717 | D17: 0.12973652 | E17: 0.070089189 | F17: 0.055740521 | G17: 9.2455773 | H17: 0.0014462549 | I17: 10.200958 | J17: 0.31718922 | K17: 73683.917 | L17: 18.087633 | M17: 2.7088946 | N17: 4.1 | O17: Yes
A18: THA | B18: 2025 | C18: 780.04765 | D18: 0.12090567 | E18: 0.09470079 | F18: 0.023937938 | G18: 8.3829455 | H18: 0.01074671 | I18: 8.901367 | J18: 0.10739265 | K18: 8056.5636 | L18: 71.619863 | M18: 2.3672666 | N18: 3.5 | P18: 58.284413 | Q18: 0
A19: SGP | B19: 2025 | C19: 883.97613 | D19: 0.083916358 | E19: 0.021084951 | F19: 0.061533966 | G19: 9.4278501 | H19: 0.010665277 | I19: 8.798662 | J19: 0.040379978 | K19: 98813.979 | L19: 6.111175 | M19: 5.194205 | N19: 4.3 | O19: Yes
A20: GBR | B20: 2025 | C20: 11249.132 | D20: 0.12537401 | G20: 7.5753638 | H20: 0.00067341762 | I20: 8.757771 | J20: 0.23468453 | K20: 57601.962 | L20: 69.487 | M20: 3.286637 | N20: 3.7 | P20: 58.205097 | Q20: 0.0562
A21: SAU | B21: 2025 | C21: 1971.4533 | D21: 0.061553023 | E21: 0.029929465 | F21: 0.030704586 | G21: 8.3244212 | H21: 0.0042224796 | I21: 6.928632 | J21: -0.0023548799 | K21: 34536.656 | L21: 36.973555 | M21: 5.2428346 | N21: 3.4 | P21: 50.649518 | Q21: 0
A22: ARE | B22: 2023 | C22: 1637.341 | D22: 0.041437707 | E22: 0.03182094 | F22: 0.0093201899 | G22: 8.415725 | H22: 0.0051398731 | I22: 5.779425 | J22: 0.046262956 | K22: 50273.513 | L22: 11.513149 | M22: 5.0900685 | N22: 4 | O22: Yes
A23: NZL | B23: 2025 | C23: 644.86167 | D23: 0.069331448 | E23: 0.0067953716 | F23: 0.062113988 | G23: 5.8547347 | H23: 0.0090790552 | I23: 5.652558 | J23: 0.027442036 | K23: 49591.041 | L23: 5.3247 | M23: 1.8104845 | N23: 3.6 | P23: 42.024301 | Q23: 0
A24: DEU | B24: 2025 | C24: 11370.136 | D24: 0.12343284 | E24: 0.030625924 | F24: 0.090049082 | G24: 7.3194772 | H24: 0.00064374581 | I24: 5.602188 | J24: 0.18844972 | K24: 60496.435 | L24: 83.491249 | M24: 0.91866739 | N24: 4.1 | P24: 56.79336 | Q24: 0.2344
A25: IDN | B25: 2025 | C25: 482.08053 | D25: 0.13070956 | G25: 5.472718 | H25: 0.01135229 | I25: 5.498633 | J25: 0.1168953 | K25: 5059.626 | L25: 285.72124 | M25: 4.8399156 | N25: 3 | P25: 51.244842 | Q25: 0
A26: KAZ | B26: 2025 | C26: 1112.4448 | D26: 0.20220174 | E26: 0.065775135 | F26: 0.12800693 | G26: 3.7026282 | H26: 0.0033283702 | I26: 3.83869 | J26: 0.034337823 | K26: 14692.133 | L26: 20.843754 | M26: 4.82 | N26: 2.7 | P26: 47.276094 | Q26: 0
A27: MEX | B27: 2025 | C27: 1408.0858 | D27: 0.15702399 | G27: 1.606483 | H27: 0.0011408985 | I27: 3.228987 | J27: 0.36535943 | K27: 13889.234 | L27: 131.9469 | M27: 2.9554593 | N27: 2.9 | P27: 47.840186 | Q27: 0
A28: BRA | B28: 2025 | C28: 436.83484 | D28: 0.16115402 | E28: 0.08942186 | F28: 0.065844241 | G28: 2.071758 | H28: 0.0047426574 | I28: 2.69162 | J28: 0.16345832 | K28: 10713.286 | L28: 212.81241 | M28: 3.3452031 | N28: 3.2 | P28: 52.480409 | Q28: 0
A29: KHM | B29: 2025 | C29: 106.62805 | D29: 0.10681116 | E29: 0.075418739 | F29: 0.02919088 | G29: 1.7534517 | H29: 0.016444563 | I29: 2.437178 | J29: 0.20140288 | K29: 2872.4293 | L29: 17.847982 | M29: 4.918442 | N29: 2.4 | P29: 34.584183 | Q29: 0
A30: FRA | B30: 2025 | C30: 9497.838 | D30: 0.12557167 | E30: 0.032220789 | F30: 0.090436927 | G30: 2.7486471 | H30: 0.00028939714 | I30: 1.718513 | J30: 0.08431496 | K30: 48985.731 | L30: 68.720337 | M30: 2.6139467 | N30: 3.9 | P30: 53.371682 | Q30: 0.0132
A31: IND | B31: 2025 | C31: 300.13407 | D31: 0.18350866 | E31: 0.10558512 | F31: 0.070481726 | G31: 0.24113432 | H31: 0.00080342201 | I31: 0.57286 | J31: 0.14604907 | K31: 2702.4799 | L31: 1463.8655 | M31: 7.8350246 | N31: 3.4 | P31: 62.915274 | Q31: 0.274
A32: POL | B32: 2025 | C32: 3758.7442 | D32: 0.16103497 | E32: 0.045898921 | F32: 0.11008334 | G32: 0.907476 | H32: 0.00024143063 | I32: 0.230952 | J32: 0.014727114 | K32: 28419.578 | L32: 36.435861 | M32: 3.8066784 | N32: 3.6 | P32: 52.546617 | Q32: 0
A33: MMR | B33: 2025 | C33: 4.1739877 | D33: -0.46787991 | E33: -0.48369272 | F33: 0.030626758 | I33: 0.1108 | J33: -0.32291503 | K33: 1488.8753 | L33: 54.850648 | M33: -2.0008647 | N33: 2.3 | P33: 3.3376877 | Q33: 0
A34: PAK | B34: 2025 | C34: 33.562658 | D34: 0.079166613 | E34: 0.046108322 | F34: 0.031601212 | I34: 0.002711 | J34: -0.49484501 | K34: 1595.9091 | L34: 255.21955 | M34: 3.5314493 | N34: 2.42 | P34: 22.687154 | Q34: 0

Sheet Korea_Exports_HS
A1: Korea exports by category (US$ M, Korea-reported, UN Comtrade)
A4: Year | B4: Sugar confectionery | C4: Chocolate | D4: Bakery & biscuits | E4: Ice cream | F4: Total
A5: 2015 | B5: 123.47 | C5: 57.76 | D5: 286.51 | E5: 39.6 | F5: 507.34
A6: 2016 | B6: 120.84 | C6: 55.52 | D6: 280.74 | E6: 44.61 | F6: 501.72
A7: 2017 | B7: 124.48 | C7: 64.72 | D7: 244.39 | E7: 46.15 | F7: 479.75
A8: 2018 | B8: 113.57 | C8: 62.25 | D8: 255.61 | E8: 47.26 | F8: 478.69
A9: 2019 | B9: 118.18 | C9: 54.9 | D9: 253.1 | E9: 54.18 | F9: 480.37
A10: 2020 | B10: 115.95 | C10: 57.88 | D10: 308.96 | E10: 60.67 | F10: 543.45
A11: 2021 | B11: 110.39 | C11: 62.38 | D11: 367.09 | E11: 72.42 | F11: 612.28
A12: 2022 | B12: 120.4 | C12: 66.75 | D12: 351.82 | E12: 77.61 | F12: 616.57
A13: 2023 | B13: 90.53 | C13: 60.96 | D13: 391.35 | E13: 93.1 | F13: 635.94
A14: 2024 | B14: 103.53 | C14: 75.59 | D14: 431.74 | E14: 98.41 | F14: 709.27
A15: 2025 | B15: 113.19 | C15: 90.77 | D15: 465.92 | E15: 118.74 | F15: 788.61
A17: CAGR 2020-25 | B17: =(B15/B10)^(1/5)-1 | C17: =(C15/C10)^(1/5)-1 | D17: =(D15/D10)^(1/5)-1 | E17: =(E15/E10)^(1/5)-1 | F17: =(F15/F10)^(1/5)-1

Sheet TAM_SAM_SOM
A1: Market sizing (HS 1704+1806+1905+2105 imports, latest year, US$ M)
A2: Edit 'In SAM?' (Y/N) and the SOM share-gain inputs. TAM excludes nothing; adjusted TAM excludes hubs, RUS, MMR.
A4: ISO3 | B4: Category imports | C4: Imports from Korea | D4: In SAM? (Y/N) | E4: Excluded from adj. TAM? (Y/N) | F4: Bakery & biscuits | G4: Chocolate | H4: Sugar confectionery | I4: Ice cream
A5: USA | B5: 20938.479 | C5: 204.53423 | D5: Y | E5: N | F5: 11412.923 | G5: 5861.3183 | H5: 3310.5604 | I5: 353.67686
A6: DEU | B6: 11370.136 | C6: 7.3194772 | D6: N | E6: N | F6: 4647.8113 | G6: 4818.8533 | H6: 1258.6771 | I6: 644.79407
A7: GBR | B7: 11249.132 | C7: 7.5753638 | D7: N | E7: N | F7: 5007.9135 | G7: 4324.9735 | H7: 1236.1405 | I7: 680.10465
A8: FRA | B8: 9497.838 | C8: 2.7486471 | D8: N | E8: N | F8: 3814.2139 | G8: 4426.7002 | H8: 780.53173 | I8: 476.39221
A9: NLD | B9: 6392.7717 | C9: 9.2455773 | D9: N | E9: Y | F9: 2561.7112 | G9: 2578.4786 | H9: 875.81319 | I9: 376.76867
A10: CAN | B10: 4964.2107 | C10: 42.41361 | D10: Y | E10: N | F10: 2343.3374 | G10: 1880.1903 | H10: 698.50057 | I10: 42.182455
A11: POL | B11: 3758.7442 | C11: 0.907476 | D11: N | E11: N | F11: 1207.67 | G11: 1872.4215 | H11: 483.53542 | I11: 195.11734
A12: AUS | B12: 2217.4183 | C12: 27.433249 | D12: N | E12: N | F12: 1136.1839 | G12: 645.22718 | H12: 315.32485 | I12: 120.68239
A13: CHN | B13: 2071.5552 | C13: 93.930646 | D13: N | E13: N | F13: 926.7918 | G13: 694.65711 | H13: 343.01317 | I13: 107.09309
A14: SAU | B14: 1971.4533 | C14: 8.3244212 | D14: Y | E14: N | F14: 909.57743 | G14: 686.2783 | H14: 235.87669 | I14: 139.72083
A15: ARE | B15: 1637.341 | C15: 8.415725 | D15: N | E15: Y | F15: 730.87588 | G15: 563.89052 | H15: 286.47198 | I15: 56.10261
A16: JPN | B16: 1600.2683 | C16: 107.11738 | D16: N | E16: N | F16: 592.80981 | G16: 780.28485 | H16: 182.93666 | I16: 44.236981
... A31: KHM | B31: 106.62805 | C31: 1.7534517 | D31: Y | E31: N | F31: 62.217428 | G31: 8.1272508 | H31: 26.240822 | I31: 10.042551
A32: PAK | B32: 33.562658 | D32: N | E32: N | F32: 5.9166933 | G32: 21.69997 | H32: 4.1222493 | I32: 1.8237454
A33: MMR | B33: 4.1739877 | D33: N | E33: Y | F33: 2.9264263 | G33: 0.59429435 | H33: 0.56434065 | I33: 0.08892645
A35: TAM (all candidate reporters) | B35: =SUM(B5:B33)
A36: Adjusted TAM (excl. hubs, RUS, MMR) | B36: =SUMIF(E5:E33,"N",B5:B33)
A37: SAM (In SAM = Y) | B37: =SUMIF(D5:D33,"Y",B5:B33)
A38: Imports from Korea within SAM | B38: =SUMIF(D5:D33,"Y",C5:C33)
A39: Korea share of SAM | B39: =B38/B37
A40: SAM — bakery & biscuits | B40: =SUMIF(D5:D33,"Y",F5:F33)
A41: SAM — chocolate | B41: =SUMIF(D5:D33,"Y",G5:G33)
A42: SAM — sugar confectionery | B42: =SUMIF(D5:D33,"Y",H5:H33)
A43: SAM — ice cream | B43: =SUMIF(D5:D33,"Y",I5:I33)
A45: SOM scenarios (illustrative)
A46: Scenario | B46: Share gain (pp of SAM) | C46: SOM (US$ M) | D46: SOM (₩ bn)
A47: Conservative | B47: 0.001 | C47: =B47*$B$37 | D47: =C47*$B$50/1000
A48: Base | B48: 0.0025 | C48: =B48*$B$37 | D48: =C48*$B$50/1000
A49: Ambitious | B49: 0.005 | C49: =B49*$B$37 | D49: =C49*$B$50/1000
A50: KRW per US$ (assumption) | B50: 1400

Sheet Competitors
A1: Competitor & alternative analysis
A2: Sources in docs/pm/09_market_research_report.md. 'UNVERIFIED' = not confirmed from a primary source.
A4: Name | B4: Category | C4: Target customer | D4: Core offering & data | E4: AI features | F4: Pricing model | G4: Strengths | H4: Gap vs WellGTM
A5: Euromonitor Passport | B5: Syndicated research | C5: Enterprise strategy & consumer-insight teams | D5: 210-country market sizes, category data, primary field research | E5: Passport AI (RAG, sourced only from Euromonitor content, Sep 2024); Passport Connect/MCP (Oct 2026) | F5: Not disclosed | G5: Depth and breadth of category data; trusted brand | H5: Browse-and-ask; no product-specific market ranking, no daily alerts, no regulation Q&A
A6: Mintel (GNPD, Leap, Spark) | B6: Syndicated research | C6: CPG marketing, innovation, R&D | D6: New-product launch database (86 economies), consumer panels, market sizes | E6: Mintel Spark (~Dec 2024), Mintel Leap, GNPD Deep Research — evidence-based on proprietary data | F6: Not disclosed (tiered) | G6: Human-verified product-launch data; consumer insight | H6: No country ranking, no monitoring alerts, no regulation Q&A; skewed to large markets
A7: Statista | B7: Statistics portal | C7: Analysts, strategy teams, consultants | D7: 1.5M+ statistics aggregated from third parties; consumer insights survey | E7: Research AI (~May 2024, cited); Connect API + MCP (Apr 2025) | F7: Not on official site; third-party estimate ~$400-600/user/yr (UNVERIFIED) | G7: Broad, citable statistics; AI-assistant integrations | H7: No trade/tariff data, no ranking, pull-only
A8: ITC Trade Map / Market Access Map / Export Potential Map | B8: Free public tool (UN/WTO) | C8: SME exporters, trade-promotion organisations, policymakers | D8: Trade flows; tariffs & NTMs; gravity-model export-potential ranking by product × market | E8: None embedded in these tools | F8: Free | G8: Closest analog to ranking logic; published methodology | H8: Generic (country-aggregate, not manufacturer-specific); not daily; no conversational Q&A; fixed weighting
A9: S&P Global Panjiva | B9: Shipment-level trade data | C9: Large enterprise procurement, supply chain, compliance | D9: Bills of lading & customs records (21 countries), company shipment histories | E9: No dedicated GenAI for Panjiva (S&P ChatIQ is in Capital IQ Pro) | F9: Not disclosed (UNVERIFIED secondary figures excluded) | G9: Granular shipment data; saved-search alerts | H9: No market ranking or synthesis; no regulation Q&A
A10: ImportGenius | B10: Shipment-level trade data | C10: SMB to Fortune 500 procurement, sales, compliance | D10: US shipment records + 25 countries (enterprise) | E10: AI HS-code enrichment (2025); Genius Company Profiler (Apr 2025) | F10: Named tiers, no public figures | G10: Trade Alerts; AI classification | H10: No market ranking; classification only, not regulation Q&A
A11: Tridge (Tridge Eye) | B11: Agri-food data & sourcing platform (Korean) | C11: Food/agri value chain: importers, manufacturers, exporters | D11: Prices, trade data, reports, sourcing marketplace; Lotte Mart named as customer | E11: Eye AI Chat (answers cite data & reports); Eye Speaker (entity-tagged alerts); Eye Echo forecasting (beta) | F11: Free/Business/Enterprise tiers, no public figures | G11: Strongest overall AI + alerting analog; Korean origin; food focus | H11: Sourcing/procurement orientation; no confirmed outbound export-destination ranking; no regulation Q&A
A12: Spate / Trendalytics | B12: AI consumer-trend tools | C12: Brand marketing & R&D (beauty, wellness, F&B) | D12: Search & social trend forecasting | E12: Ask Spate assistant; Trendalytics TrendPulse AI (Mar 2026) | F12: On request | G12: Trend detection; social-language evidence | H12: Wrong domain: ranks trends within a market, not export countries; no trade/tariff data
A13: aT KATI + ChaTi (채티) | B13: Korean public service (aT/MAFRA) | C13: Korean agri-food exporters (esp. SMEs) | D13: Export statistics, country/commodity reports, non-tariff barrier & rejection cases, buyer matching | E13: ChaTi: LLM + RAG over ~80,000 KATI documents with source links (full service Dec 2025); plan to evolve into a 'K-Food export AI agent' | F13: Free | G13: Free, Korean, K-food specific, government backed, cited answers | H13: Broad and generic; not manufacturer-specific ranking with adjustable weights or robustness; monitoring not confirmed
A14: KOTRA 해외시장뉴스 + 'AI 수출비서' (planned) | B14: Korean public service (KOTRA/MOTIE) | C14: Korean exporters across industries | D14: Country profiles, market news, promising items, tariffs/regulations | E14: 'AI 수출비서' announced Mar 2026 for first-phase launch in 2026: market/buyer recommendations, company-specific strategy reports (beta; live functionality UNVERIFIED) | F14: Free | G14: Global network of trade centres; government backing | H14: Cross-industry, generic; maturity unverified; no food-specific corrections or daily monitoring confirmed
A15: KITA K-stat / TradeNAVI | B15: Korean public service (KITA) | C15: Korean exporters | D15: Trade statistics; HS-code tariff lookup; TBT/SPS info; customs-rejection cases | E15: None confirmed | F15: Free (membership features vary) | G15: Authoritative Korean trade stats and tariffs | H15: Lookup tools, not decision support; no ranking or assistant
... A17: In-house spreadsheets | B17: Status quo | C17: Internal analysts | D17: Manual downloads + Excel/PowerPoint | E17: None | F17: Analyst time | G17: Full control; free licence | H17: Manual, inconsistent, no monitoring, prone to data traps
A19: Capability comparison (● full · ◐ partial · ○ none)
A20: Name | B20: Trade data | C20: Consumer/market data | D20: Regulation info | E20: Ranked recommendations | F20: Adjustable weights + robustness | G20: Cited AI assistant | H20: Continuous alerts | I20: Korean language
A21: Euromonitor Passport | B21: ◐ | C21: ● | D21: ○ | E21: ○ | F21: ○ | G21: ● | H21: ○ | I21: ○
A22: Mintel (GNPD, Leap, Spark) | B22: ○ | C22: ● | D22: ○ | E22: ○ | F22: ○ | G22: ● | H22: ○ | I22: ○
A23: Statista | B23: ○ | C23: ◐ | D23: ○ | E23: ○ | F23: ○ | G23: ● | H23: ○ | I23: ○
A24: ITC Trade Map / Market Access Map / Export Potential Map | B24: ● | C24: ○ | D24: ◐ | E24: ● | F24: ◐ | G24: ○ | H24: ◐ | I24: ○
A25: S&P Global Panjiva | B25: ● | C25: ○ | D25: ○ | E25: ○ | F25: ○ | G25: ○ | H25: ● | I25: ○
A26: ImportGenius | B26: ● | C26: ○ | D26: ◐ | E26: ○ | F26: ○ | G26: ◐ | H26: ● | I26: ○
A27: Tridge (Tridge Eye) | B27: ● | C27: ◐ | D27: ○ | E27: ◐ | F27: ○ | G27: ● | H27: ● | I27: ◐
A28: Spate / Trendalytics | B28: ○ | C28: ● | D28: ○ | E28: ○ | F28: ○ | G28: ◐ | H28: ◐ | I28: ○
A29: aT KATI + ChaTi (채티) | B29: ● | C29: ◐ | D29: ● | E29: ◐ | F29: ○ | G29: ● | H29: ○ | I29: ●
A30: KOTRA 해외시장뉴스 + 'AI 수출비서' (planned) | B30: ◐ | C30: ◐ | D30: ◐ | E30: ◐ | F30: ○ | G30: ◐ | H30: ○ | I30: ●
A31: KITA K-stat / TradeNAVI | B31: ● | C31: ○ | D31: ● | E31: ○ | F31: ○ | G31: ○ | H31: ○ | I31: ●
... A34: WellGTM (target) | B34: ● | C34: ◐ | D34: ● | E34: ● | F34: ● | G34: ● | H34: ● | I34: ●

Sheet Market_Trends
A1: Market trends (B2B and K-food)
A4: Theme | B4: Trend / data point | C4: Implication for WellGTM | D4: Source
A5: Category sizing | B5: No standard 'market intelligence software' category exists. Adjacent: trade compliance software US$1.95B (2025) → US$3.09B (2029), ~12% CAGR. BI software estimates range US$40-47B with 3-5x variance across firms. | C5: Size the opportunity bottom-up (customers × price), not from BI totals. | D5: The Business Research Company via GlobeNewswire, 2026-01-14; Grand View Research; Precedence Research
A6: AI adoption (all sectors) | B6: 88% of organisations use AI in ≥1 function; only ~7% fully scaled; 39% report any EBIT impact. | C6: Buyers are experimenting but sceptical of value → lead with measurable ROI. | D6: McKinsey, The State of AI, 2025-11-05
A7: AI adoption (CPG) | B7: CPG adoption of AI in ≥1 function rose 42% (2023) → 71% (2024); 56% regularly use GenAI; 'no CPG player has truly scaled'. | C7: Food/CPG is receptive but immature → design partner + pilot model fits. | D7: McKinsey, 'Fortune or fiction?…AI transformation in CPG', Oct 2024
A8: AI value gap | B8: Only 5% of firms are 'future-built'; 60% see minimal value; AI agents ≈17% of AI value in 2025, projected 29% by 2028. | C8: Agentic features must show concrete outcomes, not novelty. | D8: BCG, 'Are You Generating Value from AI?', Oct 2025
A9: ROI scepticism (retail/CPG) | B9: 75% call AI a top priority, but only 16.5% can quantify ROI. | C9: Ship an ROI model and measured time savings with the product. | D9: Deloitte, State of AI in Retail and CPG (date precision UNVERIFIED)
A10: Tariff volatility | B10: ~2/3 of trade professionals use tools to analyse trade lanes; >1/2 use tools to identify risk factors; ~75% changing sourcing. | C10: Continuous tariff/regulation monitoring is a timely buying trigger. | D10: Thomson Reuters Institute, 2025 Tariffs Survey
A11: Tariff-driven tech investment | B11: 48% investing in new tech to manage tariff workload; 51% using GenAI for trade-policy scenario modelling; 44% say tariffs influenced AI adoption. | C11: Scenario/what-if analysis (weights, tariff filters, simulation) matches demand. | D11: KPMG, 'Tariff pressures reshape tech investment', Sept 2025 survey
A12: US tariff level | B12: US effective tariff rate 16.8% (Nov 2025), highest since 1935; Korea faces a 15% baseline rate since Aug 2025. | C12: Tariff overrides with effective dates are required in scoring. | D12: Yale Budget Lab, 2025-11-17 (re-verify); USTR fact sheet Nov 2025
A13: Public AI export tools (Korea) | B13: aT launched ChaTi (cited RAG over ~80k KATI docs) Dec 2025, won a national innovation award Oct 2026, aims to become a 'K-Food export AI agent'. KOTRA plans an 'AI 수출비서' in 2026. | C13: Free public tools will cover generic Q&A → differentiate on manufacturer-specific ranking, robustness, monitoring; consider building on public data/partnering. | D13: Money Today 2026-10-20; Yonhap 2026-03-25
A14: Export vouchers | B14: 수출바우처 menu (14 categories) has no SaaS line item; closest is research/consulting (해외시장조사). | C14: Do not claim voucher eligibility; consider a 'research service' bundle and confirm with KOSMES/aT. | D14: 중소벤처기업부 공고 제2024-629호 (2024-12-30)
A15: K-food demand | B15: Agri-food exports US$10.41B in 2025 (+4.3%); biscuits & confectionery US$770M in 2024 (+17.4%); ice cream US$111M in 2025 (+21.6%). | C15: A growing exporter base needs better market selection. | D15: MAFRA 2025-01-09; Yonhap 2026-01-12 (see 02_market_analysis.md)
A16: Price vs volume | B16: Korea's HS 1704/1806/1905/2105 exports: +7.7%/yr value vs ≈0% volume (2020-25); chocolate imports +21.7% value / −13.3% volume in 2025. | C16: Corrected metrics are a differentiator vs raw-data tools. | D16: WellGTM analysis of UN Comtrade (03_data_analysis.md)

Sheet ROI_Model
A1: Illustrative ROI model (base case = hard cost savings only)
A2: ALL INPUTS ARE PLACEHOLDER ASSUMPTIONS — replace with client figures. Yellow = input, green = formula.
A4: Input | B4: Value | C4: Note
A5: Market-prioritisation studies per year | B5: 4 | C5: Placeholder
A6: Analyst effort per study — baseline (days) | B6: 45 | C6: PRD §5.3 baseline assumption
A7: Analyst effort per study — with WellGTM (days) | B7: 5 | C7: Placeholder
A8: Fully loaded analyst cost per day (₩) | B8: 500000 | C8: Placeholder
A9: Ad-hoc data requests per month | B9: 20 | C9: Placeholder
A10: Hours saved per ad-hoc request | B10: 3 | C10: Placeholder
A11: Working hours per day | B11: 8 | C11: Placeholder
A12: External consulting studies avoided per year | B12: 1 | C12: Placeholder
A13: Cost per consulting study (₩) | B13: 100000000 | C13: Placeholder
A14: Annual cost of WellGTM (₩) | B14: 60000000 | C14: Placeholder
A15: Upside: new-market entries per year | B15: 1 | C15: Placeholder
A16: Upside: cost of a failed market entry (₩) | B16: 1000000000 | C16: Placeholder
A17: Upside: reduction in failure probability (pp) | B17: 0.1 | C17: Placeholder
A19: Output | B19: Value (₩) | C19: Formula
A20: Study effort savings | B20: =B5*(B6-B7)*B8 | C20: studies × days saved × day cost
A21: Ad-hoc request savings | B21: =B9*12*B10*(B8/B11) | C21: requests × 12 × hours × hourly cost
A22: Consulting avoided | B22: =B12*B13 | C22: studies avoided × cost
A23: Total annual benefit (base) | B23: =SUM(B20:B22) | C23: sum
A24: Annual cost | B24: =B14 | C24: input
A25: Net benefit | B25: =B23-B24 | C25: benefit − cost
A26: ROI | B26: =B25/B24 | C26: net ÷ cost
A27: Payback (months) | B27: =B24/(B23/12) | C27: cost ÷ monthly benefit
A28: Upside: expected value of avoided failed entries | B28: =B15*B16*B17 | C28: not included in base ROI

Sheet VPC_Fit
A1: Value proposition fit map
A2: Severity: 4 = highest. Pains are hypotheses until validated by interviews.
A4: # | B4: Pain / gain | C4: Severity (1-4) | D4: Pain reliever / gain creator | E4: Feature (PRD) | F4: Proof metric | G4: Validated? (Y/N/Partly)
A5: P1 | B5: Data assembly takes weeks; sources fragmented | C5: 4 | D5: Automated pipeline with provenance | E5: FR-4.1, FR-3.1 | F5: Measured end-to-end time | G5: N
A6: P2 | B6: Recommendations challenged; weighting implicit | C6: 4 | D6: Explicit weights, presets, P(TOP3), TOPSIS | E6: FR-1.1–1.3, 1.12 | F6: Demo robustness | G6: N
A7: P3 | B7: Tariff/regulation changes noticed late | C7: 4 | D7: Daily refresh + anomaly alerts + e-mail brief | E7: FR-3.1–3.4 | F7: Injected-spike recall ≥ 90% | G7: N
A8: P4 | B8: Misleading data (nominal growth, hubs, mirror gaps) | C8: 3 | D8: Volume growth, hub exclusion, mirror warnings | E8: FR-1.5, 1.6, 1.10 | F8: Naive vs corrected ranking | G8: N
A9: P5 | B9: Regulations scattered, multilingual | C9: 3 | D9: Regulation RAG with dated citations | E9: FR-2.4 | F9: RAG hit@5 ≥ 85% | G9: N
A10: P6 | B10: Studies stale; consultants costly | C10: 3 | D10: Continuous monitoring; on-demand reports | E10: FR-2.7, FR-3.1 | F10: Daily job success ≥ 95% | G10: N
A11: P7 | B11: Distrust of AI numbers | C11: 3 | D11: Tools-only facts + verifier + trace | E11: FR-2.3, FR-2.6 | F11: Numeric faithfulness ≥ 95% | G11: N
A12: P8 | B12: Ad-hoc data requests eat analyst time | C12: 2 | D12: Self-service profiles, agent Q&A, export | E12: FR-1.10, FR-2.2 | F12: Minutes per request | G12: N
A13: P9 | B13: Export concentration risk not visible | C13: 2 | D13: Concentration view | E13: US-27 (Could) | F13: Concentration before/after | G13: N

Sheet Personas
A1: Persona summary (proto-personas — validate via interviews)
A4: Persona | B4: Role in buying | C4: Top goal | D4: Top pain | E4: Must-have features | F4: Validation status
A5: A. Global Market Strategy Manager | B5: Champion / primary user | C5: Defensible TOP3 per category | D5: Weeks of data work; method challenged | E5: Weights, presets, P(TOP3), cited report | F5: Not validated
A6: B. Export Sales Manager | B6: User / influencer | C6: Grow exports in own countries | D6: Learns about changes late | E6: Watchlist, alerts, country profile | F6: Not validated
A7: C. Sales Ops / Business Analyst | B7: Power user / data steward | C7: Stop rebuilding datasets | D7: Manual downloads, inconsistent numbers | E7: Provenance, export, methodology | F7: Not validated
A8: D. Regulatory Affairs / QA | B8: Influencer / can block | C8: No blocked shipments | D8: Scattered, changing rules | E8: Cited regulation RAG, change alerts | F8: Not validated
A9: E. Procurement / Raw Materials | B9: Occasional user | C9: Input-cost risk visibility | D9: Nominal growth hides cocoa effect | E9: Value vs volume, FX alerts | F9: Not validated
A10: F. Head of Global Business | B10: Economic buyer | C10: 35% overseas share by 2028 | D10: Costly, stale, inconsistent studies | E10: One-page TOP3 + confidence | F10: Not validated
A11: G. IT / Information Security | B11: Gatekeeper (H2+) | C11: Secure deployment | D11: Data leakage; unmanaged AI | E11: SSO, audit, provider choice | F11: n/a in 예선

Sheet Interview_Plan
A1: Interview recruitment plan
A2: Target 8-12 interviews before 본선. Update 'Completed' as you go.
A4: Persona | B4: Target interviews | C4: Recruited | D4: Completed | E4: % complete | F4: Recruitment channel
A5: A. Global Market Strategy Manager | B5: 3 | C5: 0 | D5: 0 | E5: =IFERROR(D5/B5,0) | F5: Challenge mentors; LinkedIn (food/CPG strategy)
A6: B. Export Sales Manager | B6: 2 | C6: 0 | D6: 0 | E6: =IFERROR(D6/B6,0) | F6: K-food export fairs; KOTRA/aT networks
A7: C. Sales Ops / Business Analyst | B7: 1 | C7: 0 | D7: 0 | E7: =IFERROR(D7/B7,0) | F7: Alumni / LinkedIn
A8: D. Regulatory Affairs / QA | B8: 2 | C8: 0 | D8: 0 | E8: =IFERROR(D8/B8,0) | F8: Food-safety associations; halal certification bodies
A9: E. Procurement / Raw Materials | B9: 1 | C9: 0 | D9: 0 | E9: =IFERROR(D9/B9,0) | F9: Industry contacts
A10: F. Head of Global Business | B10: 1 | C10: 0 | D10: 0 | E10: =IFERROR(D10/B10,0) | F10: Challenge organisers / mentors
A11: Export-support organisation advisor | B11: 2 | C11: 0 | D11: 0 | E11: =IFERROR(D11/B11,0) | F11: aT / KOTRA export desks
A12: Total | B12: =SUM(B5:B11) | C12: =SUM(C5:C11) | D12: =SUM(D5:D11) | E12: =IFERROR(D12/B12,0)

Sheet Interview_Log
A1: Interview log (one row per interview)
A2: Do not record personal data beyond what the interviewee consented to.
A4: ID | B4: Date | C4: Persona | D4: Organisation type | E4: Interviewer | F4: Consent (Y/N) | G4: Current process (summary) | H4: Top pains (quotes) | I4: Gains / desired outcomes | J4: Tools used today | K4: Reaction to demo / concept | L4: Willingness to pilot (1-5) | M4: Pain tags (P1..P9) | N4: Hypotheses supported (H#) | O4: Hypotheses contradicted (H#) | P4: Follow-ups

Sheet Survey_Responses
A1: ID | B1: Start time | C1: Completion time | D1: Email | E1: Name | F1: Which best describes your role? | G1: What type of organisation do you work for? | H1: How many export markets does your business currently sell to? | I1: How involved are you in choosing which export markets to prioritise? | J1: How often does your team run an export-market prioritisation study? | K1: How long does one market-prioritisation study usually take end-to-end? | L1: Which sources do you use today? (select all that apply) | M1: Collecting and reconciling data from different sources takes too much time. | N1: Our market recommendations are challenged because the weighting/criteria are not explicit. | O1: We learn about tariff or regulation changes in our markets too late. | P1: Market studies are out of date soon after they are finished. | Q1: It is hard to find reliable, sourced import regulations for a specific country and product. | R1: How valuable: a ranking of export markets with adjustable criteria weights? | S1: How valuable: seeing how robust the TOP3 is (probability of staying TOP3 if weights change)? | T1: How valuable: an AI assistant (Korean/English) that answers with cited sources? | U1: How valuable: e-mail alerts when something changes in markets you watch? | V1: How valuable: one-click TOP3 recommendation report (PDF) with sources? | W1: I would trust AI-generated market insights if every number links to its source. | X1: What would stop you from using a tool like this? (select all that apply) | Y1: What is the single biggest problem you face when deciding where to export next? | Z1: May we contact you for a 30-minute follow-up interview?

Sheet Survey_Analysis
A1: Survey analysis (auto-calculated from Survey_Responses rows 2-501)
A2: Paste the Microsoft Forms 'Open in Excel' export into Survey_Responses (keep the header row). Likert answers may be text ('4') or numbers.
A4: Responses received | B4: =COUNTA(Survey_Responses!A2:A501)
A6: Q1. Which best describes your role?
A7: Option | B7: Count | C7: % of responses
A8: Global Market Strategy Manager | B8: =COUNTIF(Survey_Responses!$F$2:$F$501,"Global Market Strategy Manager") | C8: =IFERROR(B8/$B$4,0)
A9: Export Sales Manager | B9: =COUNTIF(Survey_Responses!$F$2:$F$501,"Export Sales Manager") | C9: =IFERROR(B9/$B$4,0)
A10: Sales Operations / Business Analyst | B10: =COUNTIF(Survey_Responses!$F$2:$F$501,"Sales Operations / Business Analyst") | C10: =IFERROR(B10/$B$4,0)
A11: Regulatory Affairs / QA | B11: =COUNTIF(Survey_Responses!$F$2:$F$501,"Regulatory Affairs / QA") | C11: =IFERROR(B11/$B$4,0)
A12: Procurement / Raw Materials | B12: =COUNTIF(Survey_Responses!$F$2:$F$501,"Procurement / Raw Materials") | C12: =IFERROR(B12/$B$4,0)
A13: Executive (Head of Global Business) | B13: =COUNTIF(Survey_Responses!$F$2:$F$501,"Executive (Head of Global Business)") | C13: =IFERROR(B13/$B$4,0)
A14: Export-support organisation advisor | B14: =COUNTIF(Survey_Responses!$F$2:$F$501,"Export-support organisation advisor") | C14: =IFERROR(B14/$B$4,0)
A15: Other | B15: =COUNTIF(Survey_Responses!$F$2:$F$501,"Other") | C15: =IFERROR(B15/$B$4,0)
A17: Q2. What type of organisation do you work for?
A18: Option | B18: Count | C18: % of responses
A19: Large food/consumer-goods manufacturer | B19: =COUNTIF(Survey_Responses!$G$2:$G$501,"Large food/consumer-goods manufacturer") | C19: =IFERROR(B19/$B$4,0)
A20: Mid-size or small food manufacturer | B20: =COUNTIF(Survey_Responses!$G$2:$G$501,"Mid-size or small food manufacturer") | C20: =IFERROR(B20/$B$4,0)
A21: Distributor / trading company | B21: =COUNTIF(Survey_Responses!$G$2:$G$501,"Distributor / trading company") | C21: =IFERROR(B21/$B$4,0)
A22: Export-support agency or association | B22: =COUNTIF(Survey_Responses!$G$2:$G$501,"Export-support agency or association") | C22: =IFERROR(B22/$B$4,0)
A23: Other | B23: =COUNTIF(Survey_Responses!$G$2:$G$501,"Other") | C23: =IFERROR(B23/$B$4,0)
A25: Q3. How many export markets does your business currently sell to?
A26: Option | B26: Count | C26: % of responses
A27: 1-5 | B27: =COUNTIF(Survey_Responses!$H$2:$H$501,"1-5") | C27: =IFERROR(B27/$B$4,0)
A28: 6-15 | B28: =COUNTIF(Survey_Responses!$H$2:$H$501,"6-15") | C28: =IFERROR(B28/$B$4,0)
A29: 16-30 | B29: =COUNTIF(Survey_Responses!$H$2:$H$501,"16-30") | C29: =IFERROR(B29/$B$4,0)
A30: More than 30 | B30: =COUNTIF(Survey_Responses!$H$2:$H$501,"More than 30") | C30: =IFERROR(B30/$B$4,0)
A31: Don't know | B31: =COUNTIF(Survey_Responses!$H$2:$H$501,"Don't know") | C31: =IFERROR(B31/$B$4,0)
A33: Q4. How involved are you in choosing which export markets to prioritise?
A34: Option | B34: Count | C34: % of responses
A35: I make or approve the decision | B35: =COUNTIF(Survey_Responses!$I$2:$I$501,"I make or approve the decision") | C35: =IFERROR(B35/$B$4,0)
A36: I prepare the analysis/recommendation | B36: =COUNTIF(Survey_Responses!$I$2:$I$501,"I prepare the analysis/recommendation") | C36: =IFERROR(B36/$B$4,0)
A37: I provide input (e.g. sales, regulatory) | B37: =COUNTIF(Survey_Responses!$I$2:$I$501,"I provide input (e.g. sales, regulatory)") | C37: =IFERROR(B37/$B$4,0)
A38: I execute after the decision | B38: =COUNTIF(Survey_Responses!$I$2:$I$501,"I execute after the decision") | C38: =IFERROR(B38/$B$4,0)
A39: Not involved | B39: =COUNTIF(Survey_Responses!$I$2:$I$501,"Not involved") | C39: =IFERROR(B39/$B$4,0)
A41: Q5. How often does your team run an export-market prioritisation study?
A42: Option | B42: Count | C42: % of responses
A43: Monthly or more | B43: =COUNTIF(Survey_Responses!$J$2:$J$501,"Monthly or more") | C43: =IFERROR(B43/$B$4,0)
A44: Quarterly | B44: =COUNTIF(Survey_Responses!$J$2:$J$501,"Quarterly") | C44: =IFERROR(B44/$B$4,0)
A45: Once or twice a year | B45: =COUNTIF(Survey_Responses!$J$2:$J$501,"Once or twice a year") | C45: =IFERROR(B45/$B$4,0)
A46: Only when a specific opportunity arises | B46: =COUNTIF(Survey_Responses!$J$2:$J$501,"Only when a specific opportunity arises") | C46: =IFERROR(B46/$B$4,0)
...

Sheet Insight_Synthesis
A1: Hypotheses & insight synthesis
A2: Status values: To validate · Supported · Partly supported · Contradicted. Evidence count = interviews/survey items supporting.
A4: # | B4: Hypothesis | C4: Linked persona(s) | D4: Evidence needed | E4: Evidence count (+) | F4: Evidence count (−) | G4: Status | H4: Insight / implication
A5: H1 | B5: First-pass market studies take weeks and are mostly data assembly | C5: A, C | D5: Q6, interviews: time breakdown | E5: 0 | F5: 0 | G5: To validate
A6: H2 | B6: Implicit weighting causes leadership to challenge recommendations | C6: A, F | D6: Q9 ≥ 3.5 avg; interview stories | E6: 0 | F6: 0 | G6: To validate
A7: H3 | B7: Tariff/regulation changes are noticed late and cost money | C7: B, D | D7: Q10; examples of late discovery | E7: 0 | F7: 0 | G7: To validate
A8: H4 | B8: Users trust AI insights if every number is sourced | C8: All | D8: Q18 top-2-box ≥ 60% | E8: 0 | F8: 0 | G8: To validate
A9: H5 | B9: Robustness (P(TOP3)) is valued over a single ranked list | C9: A, F | D9: Q14 ≥ Q13; concept test | E9: 0 | F9: 0 | G9: To validate
A10: H6 | B10: Monitoring alerts create value between studies | C10: B, D, E | D10: Q16; pilot willingness | E10: 0 | F10: 0 | G10: To validate
A11: H7 | B11: Korean-language support is required for adoption | C11: B, D | D11: Q19 'Language support' share; interviews | E11: 0 | F11: 0 | G11: To validate
A12: H8 | B12: Data security is the main blocker for internal-data integration (Horizon 2) | C12: F, G | D12: Q19 'Data security' share | E12: 0 | F12: 0 | G12: To validate
A13: H9 | B13: Export-support organisations would use it for SME advisory (Horizon 3) | C13: Advisor | D13: Interviews with aT/KOTRA desks | E13: 0 | F13: 0 | G13: To validate

Sheet Roadmap
A1: High-level roadmap (anticipated windows; re-baseline to the official challenge schedule)
H3: 46296 | I3: 46327 | J3: 46357 | K3: 46388 | L3: 46419 | M3: 46447 | N3: 46478 | O3: 46508 | P3: 46539 | Q3: 46569 | R3: 46600 | S3: 46631 | T3: 46661 | U3: 46692 | V3: 46722 | W3: 46753 | X3: 46784 | Y3: 46813 | Z3: 46844 | AA3: 46874 | AB3: 46905 | AC3: 46935 | AD3: 46966 | AE3: 46997 | AF3: 47027 | AG3: 47058 | AH3: 47088
A4: ID | B4: Release / milestone | C4: Horizon | D4: Theme | E4: Start | F4: Finish | G4: Client objective | H4: 26-10 | I4: 26-11 | J4: 26-12 | K4: 27-01 | L4: 27-02 | M4: 27-03 | N4: 27-04 | O4: 27-05 | P4: 27-06 | Q4: 27-07 | R4: 27-08 | S4: 27-09 | T4: 27-10 | U4: 27-11 | V4: 27-12 | W4: 28-01 | X4: 28-02 | Y4: 28-03 | Z4: 28-04 | AA4: 28-05 | AB4: 28-06 | AC4: 28-07 | AD4: 28-08 | AE4: 28-09 | AF4: 28-10 | AG4: 28-11 | AH4: 28-12
A5: H1 | B5: Horizon 1 — Prove (Lotte AX Challenge) | C5: H1 | D5: Summary | E5: 46321 | F5: 46486
A6: R0 | B6: R0 Discovery & PM artefacts | C6: H1 | D6: Product | E6: 46321 | F6: 46325 | G6: Grounded problem & requirements
A7: M1 | B7: M1 Data foundation (schema, pipeline, provenance, tariffs) | C7: H1 | D7: Data | E7: 46328 | F7: 46339 | G7: Trusted evidence base
A8: M2 | B8: M2 Scoring, P(TOP3), presets, forecast engine | C8: H1 | D8: Intelligence | E8: 46342 | F8: 46353 | G8: Defensible TOP3
A9: M3 | B9: M3 API + dashboard MVP (KO/EN, warm-up) | C9: H1 | D9: Experience | E9: 46356 | F9: 46367 | G9: Decision speed
A10: M4 | B10: M4 AI agent, verifier, regulation RAG, TOP3 report | C10: H1 | D10: AI agent | E10: 46370 | F10: 46395 | G10: Trusted AI answers
A11: R10 | B11: ◆ R1.0 예선 demo-ready | C11: H1 | D11: Milestone | E11: 46395 | F11: 46395
A12: M5 | B12: M5 Monitoring: auth, daily refresh, alerts, simulation | C12: H1 | D12: Monitoring | E12: 46398 | F12: 46416 | G12: Market visibility
A13: M6 | B13: M6 Evaluation reports, time-savings, proposal, video | C13: H1 | D13: Product | E13: 46419 | F13: 46430 | G13: Credible impact claims
A14: R11 | B14: ◆ R1.1 예선 submission (anticipated) | C14: H1 | D14: Milestone | E14: 46430 | F14: 46430
A15: R20 | B15: R2.0 본선 prototype: Lotte field data, product mapping | C15: H1 | D15: Data | E15: 46447 | F15: 46479 | G15: Internal data loop
A16: R2M | B16: ◆ 본선 demo (anticipated) | C16: H1 | D16: Milestone | E16: 46486 | F16: 46486
A17: H2 | B17: Horizon 2 — Embed (pilot at Lotte Wellfood) | C17: H2 | D17: Summary | E17: 46510 | F17: 46721
A18: R30 | B18: R3.0 Enterprise pilot: SSO, security review, internal sales connector | C18: H2 | D18: Platform | E18: 46510 | F18: 46598 | G18: Overseas share 35% by 2028
A19: R31 | B19: R3.1 Product × market × entry-mode economics (Pepero, ZERO, ice cream) | C19: H2 | D19: Intelligence | E19: 46539 | F19: 46626 | G19: Pepero global mega brand
A20: R40 | B20: R4.0 Production rollout; used in annual market-priority review | C20: H2 | D20: Platform | E20: 46631 | F20: 46721 | G20: Disciplined portfolio decisions
A21: R4M | B21: ◆ R4.0 in production | C21: H2 | D21: Milestone | E21: 46721 | F21: 46721
A22: H3 | B22: Horizon 3 — Scale (multi-tenant SaaS) | C22: H3 | D22: Summary | E22: 46755 | F22: 47118
A23: R50 | B23: R5.0 Multi-tenant SaaS beta; new categories; premium data connectors | C23: H3 | D23: Platform | E23: 46755 | F23: 46934 | G23: Scale beyond one company
A24: R51 | B24: R5.1 Export-support organisation pilot | C24: H3 | D24: GTM | E24: 46846 | F24: 47025 | G24: SME export enablement
A25: R60 | B25: ◆ R6.0 General availability | C25: H3 | D25: Milestone | E25: 47102 | F25: 47102
A26: OBJ | B26: ◆ Client objective: Lotte overseas revenue share 35% (2028) | C26: H3 | D26: Client objective | E26: 47118 | F26: 47118
